============================= test session starts ==============================
platform linux -- Python 3.12.6, pytest-8.3.3, pluggy-1.5.0
rootdir: /home/abonnin/repo/sentinel3-sral-demo
configfile: pyproject.toml
plugins: cov-5.0.0, mock-3.14.0
collected 34 items

tests/src/connectors/test_eumdac_connector.py .............              [ 38%]
tests/src/processors/test_zarr_processor.py ....                         [ 50%]
tests/utils/test_logging_utils.py ......                                 [ 67%]
tests/utils/test_opensearch_query_formatter.py .........                 [ 94%]
tests/utils/test_singleton.py ..                                         [100%]

=============================== warnings summary ===============================
tests/src/processors/test_zarr_processor.py::test_save_to_zarr_collection_already_exists
  /home/abonnin/anaconda3/envs/sentinel3-sral-demo/lib/python3.12/site-packages/distributed/node.py:182: UserWarning: Port 8787 is already in use.
  Perhaps you already have a cluster running?
  Hosting the HTTP server on port 34927 instead
    warnings.warn(

-- Docs: https://docs.pytest.org/en/stable/how-to/capture-warnings.html

---------- coverage: platform linux, python 3.12.6-final-0 -----------
Name                                             Stmts   Miss  Cover   Missing
------------------------------------------------------------------------------
src/__init__.py                                      0      0   100%
src/connectors/__init__.py                           0      0   100%
src/connectors/eumdac_connector.py                  83      0   100%
src/processors/__init__.py                           0      0   100%
src/processors/zarr_processor.py                    46      0   100%
tests/__init__.py                                    0      0   100%
tests/src/connectors/test_eumdac_connector.py      135      1    99%   44
tests/src/processors/test_zarr_processor.py         56      0   100%
tests/utils/test_logging_utils.py                   50      0   100%
tests/utils/test_opensearch_query_formatter.py      32      0   100%
tests/utils/test_singleton.py                       24      0   100%
utils/__init__.py                                    0      0   100%
utils/logging_utils.py                              38      0   100%
utils/opensearch_query_formatter.py                 17      0   100%
utils/singleton.py                                   8      0   100%
------------------------------------------------------------------------------
TOTAL                                              489      1    99%

======================== 34 passed, 1 warning in 9.36s =========================
--- Logging error ---
Traceback (most recent call last):
  File "/home/abonnin/anaconda3/envs/sentinel3-sral-demo/lib/python3.12/logging/__init__.py", line 1163, in emit
    stream.write(msg + self.terminator)
ValueError: I/O operation on closed file.
Call stack:
  File "/home/abonnin/anaconda3/envs/sentinel3-sral-demo/lib/python3.12/threading.py", line 1032, in _bootstrap
    self._bootstrap_inner()
  File "/home/abonnin/anaconda3/envs/sentinel3-sral-demo/lib/python3.12/threading.py", line 1075, in _bootstrap_inner
    self.run()
  File "/home/abonnin/anaconda3/envs/sentinel3-sral-demo/lib/python3.12/threading.py", line 1012, in run
    self._target(*self._args, **self._kwargs)
  File "/home/abonnin/anaconda3/envs/sentinel3-sral-demo/lib/python3.12/site-packages/distributed/utils.py", line 451, in wrapper
    target()
  File "/home/abonnin/anaconda3/envs/sentinel3-sral-demo/lib/python3.12/site-packages/distributed/utils.py", line 559, in run_loop
    asyncio_run(amain(), loop_factory=get_loop_factory())
  File "/home/abonnin/anaconda3/envs/sentinel3-sral-demo/lib/python3.12/asyncio/runners.py", line 194, in run
    return runner.run(main)
  File "/home/abonnin/anaconda3/envs/sentinel3-sral-demo/lib/python3.12/asyncio/runners.py", line 118, in run
    return self._loop.run_until_complete(task)
  File "/home/abonnin/anaconda3/envs/sentinel3-sral-demo/lib/python3.12/asyncio/base_events.py", line 674, in run_until_complete
    self.run_forever()
  File "/home/abonnin/anaconda3/envs/sentinel3-sral-demo/lib/python3.12/asyncio/base_events.py", line 641, in run_forever
    self._run_once()
  File "/home/abonnin/anaconda3/envs/sentinel3-sral-demo/lib/python3.12/asyncio/base_events.py", line 1986, in _run_once
    handle._run()
  File "/home/abonnin/anaconda3/envs/sentinel3-sral-demo/lib/python3.12/asyncio/events.py", line 88, in _run
    self._context.run(self._callback, *self._args)
  File "/home/abonnin/anaconda3/envs/sentinel3-sral-demo/lib/python3.12/site-packages/distributed/core.py", line 831, in _handle_comm
    result = await result
  File "/home/abonnin/anaconda3/envs/sentinel3-sral-demo/lib/python3.12/site-packages/distributed/utils.py", line 808, in wrapper
    return await func(*args, **kwargs)
  File "/home/abonnin/anaconda3/envs/sentinel3-sral-demo/lib/python3.12/site-packages/distributed/scheduler.py", line 7510, in retire_workers
    logger.info("Retire worker addresses %s", workers)
Message: 'Retire worker addresses %s'
Arguments: ((0, 1, 2, 3, 4),)
--- Logging error ---
Traceback (most recent call last):
  File "/home/abonnin/anaconda3/envs/sentinel3-sral-demo/lib/python3.12/logging/__init__.py", line 1163, in emit
    stream.write(msg + self.terminator)
ValueError: I/O operation on closed file.
Call stack:
  File "/home/abonnin/anaconda3/envs/sentinel3-sral-demo/lib/python3.12/threading.py", line 1032, in _bootstrap
    self._bootstrap_inner()
  File "/home/abonnin/anaconda3/envs/sentinel3-sral-demo/lib/python3.12/threading.py", line 1075, in _bootstrap_inner
    self.run()
  File "/home/abonnin/anaconda3/envs/sentinel3-sral-demo/lib/python3.12/threading.py", line 1012, in run
    self._target(*self._args, **self._kwargs)
  File "/home/abonnin/anaconda3/envs/sentinel3-sral-demo/lib/python3.12/site-packages/distributed/utils.py", line 451, in wrapper
    target()
  File "/home/abonnin/anaconda3/envs/sentinel3-sral-demo/lib/python3.12/site-packages/distributed/utils.py", line 559, in run_loop
    asyncio_run(amain(), loop_factory=get_loop_factory())
  File "/home/abonnin/anaconda3/envs/sentinel3-sral-demo/lib/python3.12/asyncio/runners.py", line 194, in run
    return runner.run(main)
  File "/home/abonnin/anaconda3/envs/sentinel3-sral-demo/lib/python3.12/asyncio/runners.py", line 118, in run
    return self._loop.run_until_complete(task)
  File "/home/abonnin/anaconda3/envs/sentinel3-sral-demo/lib/python3.12/asyncio/base_events.py", line 674, in run_until_complete
    self.run_forever()
  File "/home/abonnin/anaconda3/envs/sentinel3-sral-demo/lib/python3.12/asyncio/base_events.py", line 641, in run_forever
    self._run_once()
  File "/home/abonnin/anaconda3/envs/sentinel3-sral-demo/lib/python3.12/asyncio/base_events.py", line 1986, in _run_once
    handle._run()
  File "/home/abonnin/anaconda3/envs/sentinel3-sral-demo/lib/python3.12/asyncio/events.py", line 88, in _run
    self._context.run(self._callback, *self._args)
  File "/home/abonnin/anaconda3/envs/sentinel3-sral-demo/lib/python3.12/site-packages/distributed/nanny.py", line 611, in close
    logger.info("Closing Nanny at %r. Reason: %s", self.address_safe, reason)
Message: 'Closing Nanny at %r. Reason: %s'
Arguments: ('tcp://127.0.0.1:32969', 'nanny-close')
--- Logging error ---
Traceback (most recent call last):
  File "/home/abonnin/anaconda3/envs/sentinel3-sral-demo/lib/python3.12/logging/__init__.py", line 1163, in emit
    stream.write(msg + self.terminator)
ValueError: I/O operation on closed file.
Call stack:
  File "/home/abonnin/anaconda3/envs/sentinel3-sral-demo/lib/python3.12/threading.py", line 1032, in _bootstrap
    self._bootstrap_inner()
  File "/home/abonnin/anaconda3/envs/sentinel3-sral-demo/lib/python3.12/threading.py", line 1075, in _bootstrap_inner
    self.run()
  File "/home/abonnin/anaconda3/envs/sentinel3-sral-demo/lib/python3.12/threading.py", line 1012, in run
    self._target(*self._args, **self._kwargs)
  File "/home/abonnin/anaconda3/envs/sentinel3-sral-demo/lib/python3.12/site-packages/distributed/utils.py", line 451, in wrapper
    target()
  File "/home/abonnin/anaconda3/envs/sentinel3-sral-demo/lib/python3.12/site-packages/distributed/utils.py", line 559, in run_loop
    asyncio_run(amain(), loop_factory=get_loop_factory())
  File "/home/abonnin/anaconda3/envs/sentinel3-sral-demo/lib/python3.12/asyncio/runners.py", line 194, in run
    return runner.run(main)
  File "/home/abonnin/anaconda3/envs/sentinel3-sral-demo/lib/python3.12/asyncio/runners.py", line 118, in run
    return self._loop.run_until_complete(task)
  File "/home/abonnin/anaconda3/envs/sentinel3-sral-demo/lib/python3.12/asyncio/base_events.py", line 674, in run_until_complete
    self.run_forever()
  File "/home/abonnin/anaconda3/envs/sentinel3-sral-demo/lib/python3.12/asyncio/base_events.py", line 641, in run_forever
    self._run_once()
  File "/home/abonnin/anaconda3/envs/sentinel3-sral-demo/lib/python3.12/asyncio/base_events.py", line 1986, in _run_once
    handle._run()
  File "/home/abonnin/anaconda3/envs/sentinel3-sral-demo/lib/python3.12/asyncio/events.py", line 88, in _run
    self._context.run(self._callback, *self._args)
  File "/home/abonnin/anaconda3/envs/sentinel3-sral-demo/lib/python3.12/site-packages/distributed/nanny.py", line 619, in close
    await self.kill(timeout=timeout, reason=reason)
  File "/home/abonnin/anaconda3/envs/sentinel3-sral-demo/lib/python3.12/site-packages/distributed/nanny.py", line 400, in kill
    await self.process.kill(reason=reason, timeout=timeout)
  File "/home/abonnin/anaconda3/envs/sentinel3-sral-demo/lib/python3.12/site-packages/distributed/nanny.py", line 850, in kill
    logger.info("Nanny asking worker to close. Reason: %s", reason)
Message: 'Nanny asking worker to close. Reason: %s'
Arguments: ('nanny-close',)
--- Logging error ---
Traceback (most recent call last):
  File "/home/abonnin/anaconda3/envs/sentinel3-sral-demo/lib/python3.12/logging/__init__.py", line 1163, in emit
    stream.write(msg + self.terminator)
ValueError: I/O operation on closed file.
Call stack:
  File "/home/abonnin/anaconda3/envs/sentinel3-sral-demo/lib/python3.12/threading.py", line 1032, in _bootstrap
    self._bootstrap_inner()
  File "/home/abonnin/anaconda3/envs/sentinel3-sral-demo/lib/python3.12/threading.py", line 1075, in _bootstrap_inner
    self.run()
  File "/home/abonnin/anaconda3/envs/sentinel3-sral-demo/lib/python3.12/threading.py", line 1012, in run
    self._target(*self._args, **self._kwargs)
  File "/home/abonnin/anaconda3/envs/sentinel3-sral-demo/lib/python3.12/site-packages/distributed/utils.py", line 451, in wrapper
    target()
  File "/home/abonnin/anaconda3/envs/sentinel3-sral-demo/lib/python3.12/site-packages/distributed/utils.py", line 559, in run_loop
    asyncio_run(amain(), loop_factory=get_loop_factory())
  File "/home/abonnin/anaconda3/envs/sentinel3-sral-demo/lib/python3.12/asyncio/runners.py", line 194, in run
    return runner.run(main)
  File "/home/abonnin/anaconda3/envs/sentinel3-sral-demo/lib/python3.12/asyncio/runners.py", line 118, in run
    return self._loop.run_until_complete(task)
  File "/home/abonnin/anaconda3/envs/sentinel3-sral-demo/lib/python3.12/asyncio/base_events.py", line 674, in run_until_complete
    self.run_forever()
  File "/home/abonnin/anaconda3/envs/sentinel3-sral-demo/lib/python3.12/asyncio/base_events.py", line 641, in run_forever
    self._run_once()
  File "/home/abonnin/anaconda3/envs/sentinel3-sral-demo/lib/python3.12/asyncio/base_events.py", line 1986, in _run_once
    handle._run()
  File "/home/abonnin/anaconda3/envs/sentinel3-sral-demo/lib/python3.12/asyncio/events.py", line 88, in _run
    self._context.run(self._callback, *self._args)
  File "/home/abonnin/anaconda3/envs/sentinel3-sral-demo/lib/python3.12/site-packages/distributed/nanny.py", line 611, in close
    logger.info("Closing Nanny at %r. Reason: %s", self.address_safe, reason)
Message: 'Closing Nanny at %r. Reason: %s'
Arguments: ('tcp://127.0.0.1:37697', 'nanny-close')
--- Logging error ---
Traceback (most recent call last):
  File "/home/abonnin/anaconda3/envs/sentinel3-sral-demo/lib/python3.12/logging/__init__.py", line 1163, in emit
    stream.write(msg + self.terminator)
ValueError: I/O operation on closed file.
Call stack:
  File "/home/abonnin/anaconda3/envs/sentinel3-sral-demo/lib/python3.12/threading.py", line 1032, in _bootstrap
    self._bootstrap_inner()
  File "/home/abonnin/anaconda3/envs/sentinel3-sral-demo/lib/python3.12/threading.py", line 1075, in _bootstrap_inner
    self.run()
  File "/home/abonnin/anaconda3/envs/sentinel3-sral-demo/lib/python3.12/threading.py", line 1012, in run
    self._target(*self._args, **self._kwargs)
  File "/home/abonnin/anaconda3/envs/sentinel3-sral-demo/lib/python3.12/site-packages/distributed/utils.py", line 451, in wrapper
    target()
  File "/home/abonnin/anaconda3/envs/sentinel3-sral-demo/lib/python3.12/site-packages/distributed/utils.py", line 559, in run_loop
    asyncio_run(amain(), loop_factory=get_loop_factory())
  File "/home/abonnin/anaconda3/envs/sentinel3-sral-demo/lib/python3.12/asyncio/runners.py", line 194, in run
    return runner.run(main)
  File "/home/abonnin/anaconda3/envs/sentinel3-sral-demo/lib/python3.12/asyncio/runners.py", line 118, in run
    return self._loop.run_until_complete(task)
  File "/home/abonnin/anaconda3/envs/sentinel3-sral-demo/lib/python3.12/asyncio/base_events.py", line 674, in run_until_complete
    self.run_forever()
  File "/home/abonnin/anaconda3/envs/sentinel3-sral-demo/lib/python3.12/asyncio/base_events.py", line 641, in run_forever
    self._run_once()
  File "/home/abonnin/anaconda3/envs/sentinel3-sral-demo/lib/python3.12/asyncio/base_events.py", line 1986, in _run_once
    handle._run()
  File "/home/abonnin/anaconda3/envs/sentinel3-sral-demo/lib/python3.12/asyncio/events.py", line 88, in _run
    self._context.run(self._callback, *self._args)
  File "/home/abonnin/anaconda3/envs/sentinel3-sral-demo/lib/python3.12/site-packages/distributed/nanny.py", line 619, in close
    await self.kill(timeout=timeout, reason=reason)
  File "/home/abonnin/anaconda3/envs/sentinel3-sral-demo/lib/python3.12/site-packages/distributed/nanny.py", line 400, in kill
    await self.process.kill(reason=reason, timeout=timeout)
  File "/home/abonnin/anaconda3/envs/sentinel3-sral-demo/lib/python3.12/site-packages/distributed/nanny.py", line 850, in kill
    logger.info("Nanny asking worker to close. Reason: %s", reason)
Message: 'Nanny asking worker to close. Reason: %s'
Arguments: ('nanny-close',)
--- Logging error ---
Traceback (most recent call last):
  File "/home/abonnin/anaconda3/envs/sentinel3-sral-demo/lib/python3.12/logging/__init__.py", line 1163, in emit
    stream.write(msg + self.terminator)
ValueError: I/O operation on closed file.
Call stack:
  File "/home/abonnin/anaconda3/envs/sentinel3-sral-demo/lib/python3.12/threading.py", line 1032, in _bootstrap
    self._bootstrap_inner()
  File "/home/abonnin/anaconda3/envs/sentinel3-sral-demo/lib/python3.12/threading.py", line 1075, in _bootstrap_inner
    self.run()
  File "/home/abonnin/anaconda3/envs/sentinel3-sral-demo/lib/python3.12/threading.py", line 1012, in run
    self._target(*self._args, **self._kwargs)
  File "/home/abonnin/anaconda3/envs/sentinel3-sral-demo/lib/python3.12/site-packages/distributed/utils.py", line 451, in wrapper
    target()
  File "/home/abonnin/anaconda3/envs/sentinel3-sral-demo/lib/python3.12/site-packages/distributed/utils.py", line 559, in run_loop
    asyncio_run(amain(), loop_factory=get_loop_factory())
  File "/home/abonnin/anaconda3/envs/sentinel3-sral-demo/lib/python3.12/asyncio/runners.py", line 194, in run
    return runner.run(main)
  File "/home/abonnin/anaconda3/envs/sentinel3-sral-demo/lib/python3.12/asyncio/runners.py", line 118, in run
    return self._loop.run_until_complete(task)
  File "/home/abonnin/anaconda3/envs/sentinel3-sral-demo/lib/python3.12/asyncio/base_events.py", line 674, in run_until_complete
    self.run_forever()
  File "/home/abonnin/anaconda3/envs/sentinel3-sral-demo/lib/python3.12/asyncio/base_events.py", line 641, in run_forever
    self._run_once()
  File "/home/abonnin/anaconda3/envs/sentinel3-sral-demo/lib/python3.12/asyncio/base_events.py", line 1986, in _run_once
    handle._run()
  File "/home/abonnin/anaconda3/envs/sentinel3-sral-demo/lib/python3.12/asyncio/events.py", line 88, in _run
    self._context.run(self._callback, *self._args)
  File "/home/abonnin/anaconda3/envs/sentinel3-sral-demo/lib/python3.12/site-packages/distributed/nanny.py", line 611, in close
    logger.info("Closing Nanny at %r. Reason: %s", self.address_safe, reason)
Message: 'Closing Nanny at %r. Reason: %s'
Arguments: ('tcp://127.0.0.1:45895', 'nanny-close')
--- Logging error ---
Traceback (most recent call last):
  File "/home/abonnin/anaconda3/envs/sentinel3-sral-demo/lib/python3.12/logging/__init__.py", line 1163, in emit
    stream.write(msg + self.terminator)
ValueError: I/O operation on closed file.
Call stack:
  File "/home/abonnin/anaconda3/envs/sentinel3-sral-demo/lib/python3.12/threading.py", line 1032, in _bootstrap
    self._bootstrap_inner()
  File "/home/abonnin/anaconda3/envs/sentinel3-sral-demo/lib/python3.12/threading.py", line 1075, in _bootstrap_inner
    self.run()
  File "/home/abonnin/anaconda3/envs/sentinel3-sral-demo/lib/python3.12/threading.py", line 1012, in run
    self._target(*self._args, **self._kwargs)
  File "/home/abonnin/anaconda3/envs/sentinel3-sral-demo/lib/python3.12/site-packages/distributed/utils.py", line 451, in wrapper
    target()
  File "/home/abonnin/anaconda3/envs/sentinel3-sral-demo/lib/python3.12/site-packages/distributed/utils.py", line 559, in run_loop
    asyncio_run(amain(), loop_factory=get_loop_factory())
  File "/home/abonnin/anaconda3/envs/sentinel3-sral-demo/lib/python3.12/asyncio/runners.py", line 194, in run
    return runner.run(main)
  File "/home/abonnin/anaconda3/envs/sentinel3-sral-demo/lib/python3.12/asyncio/runners.py", line 118, in run
    return self._loop.run_until_complete(task)
  File "/home/abonnin/anaconda3/envs/sentinel3-sral-demo/lib/python3.12/asyncio/base_events.py", line 674, in run_until_complete
    self.run_forever()
  File "/home/abonnin/anaconda3/envs/sentinel3-sral-demo/lib/python3.12/asyncio/base_events.py", line 641, in run_forever
    self._run_once()
  File "/home/abonnin/anaconda3/envs/sentinel3-sral-demo/lib/python3.12/asyncio/base_events.py", line 1986, in _run_once
    handle._run()
  File "/home/abonnin/anaconda3/envs/sentinel3-sral-demo/lib/python3.12/asyncio/events.py", line 88, in _run
    self._context.run(self._callback, *self._args)
  File "/home/abonnin/anaconda3/envs/sentinel3-sral-demo/lib/python3.12/site-packages/distributed/nanny.py", line 619, in close
    await self.kill(timeout=timeout, reason=reason)
  File "/home/abonnin/anaconda3/envs/sentinel3-sral-demo/lib/python3.12/site-packages/distributed/nanny.py", line 400, in kill
    await self.process.kill(reason=reason, timeout=timeout)
  File "/home/abonnin/anaconda3/envs/sentinel3-sral-demo/lib/python3.12/site-packages/distributed/nanny.py", line 850, in kill
    logger.info("Nanny asking worker to close. Reason: %s", reason)
Message: 'Nanny asking worker to close. Reason: %s'
Arguments: ('nanny-close',)
--- Logging error ---
Traceback (most recent call last):
  File "/home/abonnin/anaconda3/envs/sentinel3-sral-demo/lib/python3.12/logging/__init__.py", line 1163, in emit
    stream.write(msg + self.terminator)
ValueError: I/O operation on closed file.
Call stack:
  File "/home/abonnin/anaconda3/envs/sentinel3-sral-demo/lib/python3.12/threading.py", line 1032, in _bootstrap
    self._bootstrap_inner()
  File "/home/abonnin/anaconda3/envs/sentinel3-sral-demo/lib/python3.12/threading.py", line 1075, in _bootstrap_inner
    self.run()
  File "/home/abonnin/anaconda3/envs/sentinel3-sral-demo/lib/python3.12/threading.py", line 1012, in run
    self._target(*self._args, **self._kwargs)
  File "/home/abonnin/anaconda3/envs/sentinel3-sral-demo/lib/python3.12/site-packages/distributed/utils.py", line 451, in wrapper
    target()
  File "/home/abonnin/anaconda3/envs/sentinel3-sral-demo/lib/python3.12/site-packages/distributed/utils.py", line 559, in run_loop
    asyncio_run(amain(), loop_factory=get_loop_factory())
  File "/home/abonnin/anaconda3/envs/sentinel3-sral-demo/lib/python3.12/asyncio/runners.py", line 194, in run
    return runner.run(main)
  File "/home/abonnin/anaconda3/envs/sentinel3-sral-demo/lib/python3.12/asyncio/runners.py", line 118, in run
    return self._loop.run_until_complete(task)
  File "/home/abonnin/anaconda3/envs/sentinel3-sral-demo/lib/python3.12/asyncio/base_events.py", line 674, in run_until_complete
    self.run_forever()
  File "/home/abonnin/anaconda3/envs/sentinel3-sral-demo/lib/python3.12/asyncio/base_events.py", line 641, in run_forever
    self._run_once()
  File "/home/abonnin/anaconda3/envs/sentinel3-sral-demo/lib/python3.12/asyncio/base_events.py", line 1986, in _run_once
    handle._run()
  File "/home/abonnin/anaconda3/envs/sentinel3-sral-demo/lib/python3.12/asyncio/events.py", line 88, in _run
    self._context.run(self._callback, *self._args)
  File "/home/abonnin/anaconda3/envs/sentinel3-sral-demo/lib/python3.12/site-packages/distributed/nanny.py", line 611, in close
    logger.info("Closing Nanny at %r. Reason: %s", self.address_safe, reason)
Message: 'Closing Nanny at %r. Reason: %s'
Arguments: ('tcp://127.0.0.1:37583', 'nanny-close')
--- Logging error ---
Traceback (most recent call last):
  File "/home/abonnin/anaconda3/envs/sentinel3-sral-demo/lib/python3.12/logging/__init__.py", line 1163, in emit
    stream.write(msg + self.terminator)
ValueError: I/O operation on closed file.
Call stack:
  File "/home/abonnin/anaconda3/envs/sentinel3-sral-demo/lib/python3.12/threading.py", line 1032, in _bootstrap
    self._bootstrap_inner()
  File "/home/abonnin/anaconda3/envs/sentinel3-sral-demo/lib/python3.12/threading.py", line 1075, in _bootstrap_inner
    self.run()
  File "/home/abonnin/anaconda3/envs/sentinel3-sral-demo/lib/python3.12/threading.py", line 1012, in run
    self._target(*self._args, **self._kwargs)
  File "/home/abonnin/anaconda3/envs/sentinel3-sral-demo/lib/python3.12/site-packages/distributed/utils.py", line 451, in wrapper
    target()
  File "/home/abonnin/anaconda3/envs/sentinel3-sral-demo/lib/python3.12/site-packages/distributed/utils.py", line 559, in run_loop
    asyncio_run(amain(), loop_factory=get_loop_factory())
  File "/home/abonnin/anaconda3/envs/sentinel3-sral-demo/lib/python3.12/asyncio/runners.py", line 194, in run
    return runner.run(main)
  File "/home/abonnin/anaconda3/envs/sentinel3-sral-demo/lib/python3.12/asyncio/runners.py", line 118, in run
    return self._loop.run_until_complete(task)
  File "/home/abonnin/anaconda3/envs/sentinel3-sral-demo/lib/python3.12/asyncio/base_events.py", line 674, in run_until_complete
    self.run_forever()
  File "/home/abonnin/anaconda3/envs/sentinel3-sral-demo/lib/python3.12/asyncio/base_events.py", line 641, in run_forever
    self._run_once()
  File "/home/abonnin/anaconda3/envs/sentinel3-sral-demo/lib/python3.12/asyncio/base_events.py", line 1986, in _run_once
    handle._run()
  File "/home/abonnin/anaconda3/envs/sentinel3-sral-demo/lib/python3.12/asyncio/events.py", line 88, in _run
    self._context.run(self._callback, *self._args)
  File "/home/abonnin/anaconda3/envs/sentinel3-sral-demo/lib/python3.12/site-packages/distributed/nanny.py", line 619, in close
    await self.kill(timeout=timeout, reason=reason)
  File "/home/abonnin/anaconda3/envs/sentinel3-sral-demo/lib/python3.12/site-packages/distributed/nanny.py", line 400, in kill
    await self.process.kill(reason=reason, timeout=timeout)
  File "/home/abonnin/anaconda3/envs/sentinel3-sral-demo/lib/python3.12/site-packages/distributed/nanny.py", line 850, in kill
    logger.info("Nanny asking worker to close. Reason: %s", reason)
Message: 'Nanny asking worker to close. Reason: %s'
Arguments: ('nanny-close',)
--- Logging error ---
Traceback (most recent call last):
  File "/home/abonnin/anaconda3/envs/sentinel3-sral-demo/lib/python3.12/logging/__init__.py", line 1163, in emit
    stream.write(msg + self.terminator)
ValueError: I/O operation on closed file.
Call stack:
  File "/home/abonnin/anaconda3/envs/sentinel3-sral-demo/lib/python3.12/threading.py", line 1032, in _bootstrap
    self._bootstrap_inner()
  File "/home/abonnin/anaconda3/envs/sentinel3-sral-demo/lib/python3.12/threading.py", line 1075, in _bootstrap_inner
    self.run()
  File "/home/abonnin/anaconda3/envs/sentinel3-sral-demo/lib/python3.12/threading.py", line 1012, in run
    self._target(*self._args, **self._kwargs)
  File "/home/abonnin/anaconda3/envs/sentinel3-sral-demo/lib/python3.12/site-packages/distributed/utils.py", line 451, in wrapper
    target()
  File "/home/abonnin/anaconda3/envs/sentinel3-sral-demo/lib/python3.12/site-packages/distributed/utils.py", line 559, in run_loop
    asyncio_run(amain(), loop_factory=get_loop_factory())
  File "/home/abonnin/anaconda3/envs/sentinel3-sral-demo/lib/python3.12/asyncio/runners.py", line 194, in run
    return runner.run(main)
  File "/home/abonnin/anaconda3/envs/sentinel3-sral-demo/lib/python3.12/asyncio/runners.py", line 118, in run
    return self._loop.run_until_complete(task)
  File "/home/abonnin/anaconda3/envs/sentinel3-sral-demo/lib/python3.12/asyncio/base_events.py", line 674, in run_until_complete
    self.run_forever()
  File "/home/abonnin/anaconda3/envs/sentinel3-sral-demo/lib/python3.12/asyncio/base_events.py", line 641, in run_forever
    self._run_once()
  File "/home/abonnin/anaconda3/envs/sentinel3-sral-demo/lib/python3.12/asyncio/base_events.py", line 1986, in _run_once
    handle._run()
  File "/home/abonnin/anaconda3/envs/sentinel3-sral-demo/lib/python3.12/asyncio/events.py", line 88, in _run
    self._context.run(self._callback, *self._args)
  File "/home/abonnin/anaconda3/envs/sentinel3-sral-demo/lib/python3.12/site-packages/distributed/nanny.py", line 611, in close
    logger.info("Closing Nanny at %r. Reason: %s", self.address_safe, reason)
Message: 'Closing Nanny at %r. Reason: %s'
Arguments: ('tcp://127.0.0.1:35485', 'nanny-close')
--- Logging error ---
Traceback (most recent call last):
  File "/home/abonnin/anaconda3/envs/sentinel3-sral-demo/lib/python3.12/logging/__init__.py", line 1163, in emit
    stream.write(msg + self.terminator)
ValueError: I/O operation on closed file.
Call stack:
  File "/home/abonnin/anaconda3/envs/sentinel3-sral-demo/lib/python3.12/threading.py", line 1032, in _bootstrap
    self._bootstrap_inner()
  File "/home/abonnin/anaconda3/envs/sentinel3-sral-demo/lib/python3.12/threading.py", line 1075, in _bootstrap_inner
    self.run()
  File "/home/abonnin/anaconda3/envs/sentinel3-sral-demo/lib/python3.12/threading.py", line 1012, in run
    self._target(*self._args, **self._kwargs)
  File "/home/abonnin/anaconda3/envs/sentinel3-sral-demo/lib/python3.12/site-packages/distributed/utils.py", line 451, in wrapper
    target()
  File "/home/abonnin/anaconda3/envs/sentinel3-sral-demo/lib/python3.12/site-packages/distributed/utils.py", line 559, in run_loop
    asyncio_run(amain(), loop_factory=get_loop_factory())
  File "/home/abonnin/anaconda3/envs/sentinel3-sral-demo/lib/python3.12/asyncio/runners.py", line 194, in run
    return runner.run(main)
  File "/home/abonnin/anaconda3/envs/sentinel3-sral-demo/lib/python3.12/asyncio/runners.py", line 118, in run
    return self._loop.run_until_complete(task)
  File "/home/abonnin/anaconda3/envs/sentinel3-sral-demo/lib/python3.12/asyncio/base_events.py", line 674, in run_until_complete
    self.run_forever()
  File "/home/abonnin/anaconda3/envs/sentinel3-sral-demo/lib/python3.12/asyncio/base_events.py", line 641, in run_forever
    self._run_once()
  File "/home/abonnin/anaconda3/envs/sentinel3-sral-demo/lib/python3.12/asyncio/base_events.py", line 1986, in _run_once
    handle._run()
  File "/home/abonnin/anaconda3/envs/sentinel3-sral-demo/lib/python3.12/asyncio/events.py", line 88, in _run
    self._context.run(self._callback, *self._args)
  File "/home/abonnin/anaconda3/envs/sentinel3-sral-demo/lib/python3.12/site-packages/distributed/nanny.py", line 619, in close
    await self.kill(timeout=timeout, reason=reason)
  File "/home/abonnin/anaconda3/envs/sentinel3-sral-demo/lib/python3.12/site-packages/distributed/nanny.py", line 400, in kill
    await self.process.kill(reason=reason, timeout=timeout)
  File "/home/abonnin/anaconda3/envs/sentinel3-sral-demo/lib/python3.12/site-packages/distributed/nanny.py", line 850, in kill
    logger.info("Nanny asking worker to close. Reason: %s", reason)
Message: 'Nanny asking worker to close. Reason: %s'
Arguments: ('nanny-close',)
--- Logging error ---
Traceback (most recent call last):
  File "/home/abonnin/anaconda3/envs/sentinel3-sral-demo/lib/python3.12/logging/__init__.py", line 1163, in emit
    stream.write(msg + self.terminator)
ValueError: I/O operation on closed file.
Call stack:
  File "/home/abonnin/anaconda3/envs/sentinel3-sral-demo/lib/python3.12/threading.py", line 1032, in _bootstrap
    self._bootstrap_inner()
  File "/home/abonnin/anaconda3/envs/sentinel3-sral-demo/lib/python3.12/threading.py", line 1075, in _bootstrap_inner
    self.run()
  File "/home/abonnin/anaconda3/envs/sentinel3-sral-demo/lib/python3.12/threading.py", line 1012, in run
    self._target(*self._args, **self._kwargs)
  File "/home/abonnin/anaconda3/envs/sentinel3-sral-demo/lib/python3.12/site-packages/distributed/utils.py", line 451, in wrapper
    target()
  File "/home/abonnin/anaconda3/envs/sentinel3-sral-demo/lib/python3.12/site-packages/distributed/utils.py", line 559, in run_loop
    asyncio_run(amain(), loop_factory=get_loop_factory())
  File "/home/abonnin/anaconda3/envs/sentinel3-sral-demo/lib/python3.12/asyncio/runners.py", line 194, in run
    return runner.run(main)
  File "/home/abonnin/anaconda3/envs/sentinel3-sral-demo/lib/python3.12/asyncio/runners.py", line 118, in run
    return self._loop.run_until_complete(task)
  File "/home/abonnin/anaconda3/envs/sentinel3-sral-demo/lib/python3.12/asyncio/base_events.py", line 674, in run_until_complete
    self.run_forever()
  File "/home/abonnin/anaconda3/envs/sentinel3-sral-demo/lib/python3.12/asyncio/base_events.py", line 641, in run_forever
    self._run_once()
  File "/home/abonnin/anaconda3/envs/sentinel3-sral-demo/lib/python3.12/asyncio/base_events.py", line 1986, in _run_once
    handle._run()
  File "/home/abonnin/anaconda3/envs/sentinel3-sral-demo/lib/python3.12/asyncio/events.py", line 88, in _run
    self._context.run(self._callback, *self._args)
  File "/home/abonnin/anaconda3/envs/sentinel3-sral-demo/lib/python3.12/site-packages/distributed/core.py", line 831, in _handle_comm
    result = await result
  File "/home/abonnin/anaconda3/envs/sentinel3-sral-demo/lib/python3.12/site-packages/distributed/utils.py", line 808, in wrapper
    return await func(*args, **kwargs)
  File "/home/abonnin/anaconda3/envs/sentinel3-sral-demo/lib/python3.12/site-packages/distributed/scheduler.py", line 4602, in add_worker
    await self.handle_worker(comm, address)
  File "/home/abonnin/anaconda3/envs/sentinel3-sral-demo/lib/python3.12/site-packages/distributed/scheduler.py", line 6124, in handle_worker
    await self.handle_stream(comm=comm, extra={"worker": worker})
  File "/home/abonnin/anaconda3/envs/sentinel3-sral-demo/lib/python3.12/site-packages/distributed/core.py", line 905, in handle_stream
    logger.info(
Message: "Received 'close-stream' from %s; closing."
Arguments: ('tcp://127.0.0.1:34358',)
--- Logging error ---
Traceback (most recent call last):
  File "/home/abonnin/anaconda3/envs/sentinel3-sral-demo/lib/python3.12/logging/__init__.py", line 1163, in emit
    stream.write(msg + self.terminator)
ValueError: I/O operation on closed file.
Call stack:
  File "/home/abonnin/anaconda3/envs/sentinel3-sral-demo/lib/python3.12/threading.py", line 1032, in _bootstrap
    self._bootstrap_inner()
  File "/home/abonnin/anaconda3/envs/sentinel3-sral-demo/lib/python3.12/threading.py", line 1075, in _bootstrap_inner
    self.run()
  File "/home/abonnin/anaconda3/envs/sentinel3-sral-demo/lib/python3.12/threading.py", line 1012, in run
    self._target(*self._args, **self._kwargs)
  File "/home/abonnin/anaconda3/envs/sentinel3-sral-demo/lib/python3.12/site-packages/distributed/utils.py", line 451, in wrapper
    target()
  File "/home/abonnin/anaconda3/envs/sentinel3-sral-demo/lib/python3.12/site-packages/distributed/utils.py", line 559, in run_loop
    asyncio_run(amain(), loop_factory=get_loop_factory())
  File "/home/abonnin/anaconda3/envs/sentinel3-sral-demo/lib/python3.12/asyncio/runners.py", line 194, in run
    return runner.run(main)
  File "/home/abonnin/anaconda3/envs/sentinel3-sral-demo/lib/python3.12/asyncio/runners.py", line 118, in run
    return self._loop.run_until_complete(task)
  File "/home/abonnin/anaconda3/envs/sentinel3-sral-demo/lib/python3.12/asyncio/base_events.py", line 674, in run_until_complete
    self.run_forever()
  File "/home/abonnin/anaconda3/envs/sentinel3-sral-demo/lib/python3.12/asyncio/base_events.py", line 641, in run_forever
    self._run_once()
  File "/home/abonnin/anaconda3/envs/sentinel3-sral-demo/lib/python3.12/asyncio/base_events.py", line 1986, in _run_once
    handle._run()
  File "/home/abonnin/anaconda3/envs/sentinel3-sral-demo/lib/python3.12/asyncio/events.py", line 88, in _run
    self._context.run(self._callback, *self._args)
  File "/home/abonnin/anaconda3/envs/sentinel3-sral-demo/lib/python3.12/site-packages/distributed/core.py", line 831, in _handle_comm
    result = await result
  File "/home/abonnin/anaconda3/envs/sentinel3-sral-demo/lib/python3.12/site-packages/distributed/utils.py", line 808, in wrapper
    return await func(*args, **kwargs)
  File "/home/abonnin/anaconda3/envs/sentinel3-sral-demo/lib/python3.12/site-packages/distributed/scheduler.py", line 4602, in add_worker
    await self.handle_worker(comm, address)
  File "/home/abonnin/anaconda3/envs/sentinel3-sral-demo/lib/python3.12/site-packages/distributed/scheduler.py", line 6124, in handle_worker
    await self.handle_stream(comm=comm, extra={"worker": worker})
  File "/home/abonnin/anaconda3/envs/sentinel3-sral-demo/lib/python3.12/site-packages/distributed/core.py", line 905, in handle_stream
    logger.info(
Message: "Received 'close-stream' from %s; closing."
Arguments: ('tcp://127.0.0.1:34364',)
--- Logging error ---
Traceback (most recent call last):
  File "/home/abonnin/anaconda3/envs/sentinel3-sral-demo/lib/python3.12/logging/__init__.py", line 1163, in emit
    stream.write(msg + self.terminator)
ValueError: I/O operation on closed file.
Call stack:
  File "/home/abonnin/anaconda3/envs/sentinel3-sral-demo/lib/python3.12/threading.py", line 1032, in _bootstrap
    self._bootstrap_inner()
  File "/home/abonnin/anaconda3/envs/sentinel3-sral-demo/lib/python3.12/threading.py", line 1075, in _bootstrap_inner
    self.run()
  File "/home/abonnin/anaconda3/envs/sentinel3-sral-demo/lib/python3.12/threading.py", line 1012, in run
    self._target(*self._args, **self._kwargs)
  File "/home/abonnin/anaconda3/envs/sentinel3-sral-demo/lib/python3.12/site-packages/distributed/utils.py", line 451, in wrapper
    target()
  File "/home/abonnin/anaconda3/envs/sentinel3-sral-demo/lib/python3.12/site-packages/distributed/utils.py", line 559, in run_loop
    asyncio_run(amain(), loop_factory=get_loop_factory())
  File "/home/abonnin/anaconda3/envs/sentinel3-sral-demo/lib/python3.12/asyncio/runners.py", line 194, in run
    return runner.run(main)
  File "/home/abonnin/anaconda3/envs/sentinel3-sral-demo/lib/python3.12/asyncio/runners.py", line 118, in run
    return self._loop.run_until_complete(task)
  File "/home/abonnin/anaconda3/envs/sentinel3-sral-demo/lib/python3.12/asyncio/base_events.py", line 674, in run_until_complete
    self.run_forever()
  File "/home/abonnin/anaconda3/envs/sentinel3-sral-demo/lib/python3.12/asyncio/base_events.py", line 641, in run_forever
    self._run_once()
  File "/home/abonnin/anaconda3/envs/sentinel3-sral-demo/lib/python3.12/asyncio/base_events.py", line 1986, in _run_once
    handle._run()
  File "/home/abonnin/anaconda3/envs/sentinel3-sral-demo/lib/python3.12/asyncio/events.py", line 88, in _run
    self._context.run(self._callback, *self._args)
  File "/home/abonnin/anaconda3/envs/sentinel3-sral-demo/lib/python3.12/site-packages/distributed/core.py", line 831, in _handle_comm
    result = await result
  File "/home/abonnin/anaconda3/envs/sentinel3-sral-demo/lib/python3.12/site-packages/distributed/utils.py", line 808, in wrapper
    return await func(*args, **kwargs)
  File "/home/abonnin/anaconda3/envs/sentinel3-sral-demo/lib/python3.12/site-packages/distributed/scheduler.py", line 4602, in add_worker
    await self.handle_worker(comm, address)
  File "/home/abonnin/anaconda3/envs/sentinel3-sral-demo/lib/python3.12/site-packages/distributed/scheduler.py", line 6124, in handle_worker
    await self.handle_stream(comm=comm, extra={"worker": worker})
  File "/home/abonnin/anaconda3/envs/sentinel3-sral-demo/lib/python3.12/site-packages/distributed/core.py", line 905, in handle_stream
    logger.info(
Message: "Received 'close-stream' from %s; closing."
Arguments: ('tcp://127.0.0.1:34370',)
--- Logging error ---
Traceback (most recent call last):
  File "/home/abonnin/anaconda3/envs/sentinel3-sral-demo/lib/python3.12/logging/__init__.py", line 1163, in emit
    stream.write(msg + self.terminator)
ValueError: I/O operation on closed file.
Call stack:
  File "/home/abonnin/anaconda3/envs/sentinel3-sral-demo/lib/python3.12/threading.py", line 1032, in _bootstrap
    self._bootstrap_inner()
  File "/home/abonnin/anaconda3/envs/sentinel3-sral-demo/lib/python3.12/threading.py", line 1075, in _bootstrap_inner
    self.run()
  File "/home/abonnin/anaconda3/envs/sentinel3-sral-demo/lib/python3.12/threading.py", line 1012, in run
    self._target(*self._args, **self._kwargs)
  File "/home/abonnin/anaconda3/envs/sentinel3-sral-demo/lib/python3.12/site-packages/distributed/utils.py", line 451, in wrapper
    target()
  File "/home/abonnin/anaconda3/envs/sentinel3-sral-demo/lib/python3.12/site-packages/distributed/utils.py", line 559, in run_loop
    asyncio_run(amain(), loop_factory=get_loop_factory())
  File "/home/abonnin/anaconda3/envs/sentinel3-sral-demo/lib/python3.12/asyncio/runners.py", line 194, in run
    return runner.run(main)
  File "/home/abonnin/anaconda3/envs/sentinel3-sral-demo/lib/python3.12/asyncio/runners.py", line 118, in run
    return self._loop.run_until_complete(task)
  File "/home/abonnin/anaconda3/envs/sentinel3-sral-demo/lib/python3.12/asyncio/base_events.py", line 674, in run_until_complete
    self.run_forever()
  File "/home/abonnin/anaconda3/envs/sentinel3-sral-demo/lib/python3.12/asyncio/base_events.py", line 641, in run_forever
    self._run_once()
  File "/home/abonnin/anaconda3/envs/sentinel3-sral-demo/lib/python3.12/asyncio/base_events.py", line 1986, in _run_once
    handle._run()
  File "/home/abonnin/anaconda3/envs/sentinel3-sral-demo/lib/python3.12/asyncio/events.py", line 88, in _run
    self._context.run(self._callback, *self._args)
  File "/home/abonnin/anaconda3/envs/sentinel3-sral-demo/lib/python3.12/site-packages/distributed/core.py", line 831, in _handle_comm
    result = await result
  File "/home/abonnin/anaconda3/envs/sentinel3-sral-demo/lib/python3.12/site-packages/distributed/utils.py", line 808, in wrapper
    return await func(*args, **kwargs)
  File "/home/abonnin/anaconda3/envs/sentinel3-sral-demo/lib/python3.12/site-packages/distributed/scheduler.py", line 4602, in add_worker
    await self.handle_worker(comm, address)
  File "/home/abonnin/anaconda3/envs/sentinel3-sral-demo/lib/python3.12/site-packages/distributed/scheduler.py", line 6128, in handle_worker
    await self.remove_worker(
  File "/home/abonnin/anaconda3/envs/sentinel3-sral-demo/lib/python3.12/site-packages/distributed/utils.py", line 808, in wrapper
    return await func(*args, **kwargs)
  File "/home/abonnin/anaconda3/envs/sentinel3-sral-demo/lib/python3.12/site-packages/distributed/scheduler.py", line 5388, in remove_worker
    logger.info(f"Remove worker {ws} ({stimulus_id=})")
Message: "Remove worker <WorkerState 'tcp://127.0.0.1:40635', name: 0, status: closing, memory: 0, processing: 0> (stimulus_id='handle-worker-cleanup-1727764396.0893452')"
Arguments: ()
--- Logging error ---
Traceback (most recent call last):
  File "/home/abonnin/anaconda3/envs/sentinel3-sral-demo/lib/python3.12/logging/__init__.py", line 1163, in emit
    stream.write(msg + self.terminator)
ValueError: I/O operation on closed file.
Call stack:
  File "/home/abonnin/anaconda3/envs/sentinel3-sral-demo/lib/python3.12/threading.py", line 1032, in _bootstrap
    self._bootstrap_inner()
  File "/home/abonnin/anaconda3/envs/sentinel3-sral-demo/lib/python3.12/threading.py", line 1075, in _bootstrap_inner
    self.run()
  File "/home/abonnin/anaconda3/envs/sentinel3-sral-demo/lib/python3.12/threading.py", line 1012, in run
    self._target(*self._args, **self._kwargs)
  File "/home/abonnin/anaconda3/envs/sentinel3-sral-demo/lib/python3.12/site-packages/distributed/utils.py", line 451, in wrapper
    target()
  File "/home/abonnin/anaconda3/envs/sentinel3-sral-demo/lib/python3.12/site-packages/distributed/utils.py", line 559, in run_loop
    asyncio_run(amain(), loop_factory=get_loop_factory())
  File "/home/abonnin/anaconda3/envs/sentinel3-sral-demo/lib/python3.12/asyncio/runners.py", line 194, in run
    return runner.run(main)
  File "/home/abonnin/anaconda3/envs/sentinel3-sral-demo/lib/python3.12/asyncio/runners.py", line 118, in run
    return self._loop.run_until_complete(task)
  File "/home/abonnin/anaconda3/envs/sentinel3-sral-demo/lib/python3.12/asyncio/base_events.py", line 674, in run_until_complete
    self.run_forever()
  File "/home/abonnin/anaconda3/envs/sentinel3-sral-demo/lib/python3.12/asyncio/base_events.py", line 641, in run_forever
    self._run_once()
  File "/home/abonnin/anaconda3/envs/sentinel3-sral-demo/lib/python3.12/asyncio/base_events.py", line 1986, in _run_once
    handle._run()
  File "/home/abonnin/anaconda3/envs/sentinel3-sral-demo/lib/python3.12/asyncio/events.py", line 88, in _run
    self._context.run(self._callback, *self._args)
  File "/home/abonnin/anaconda3/envs/sentinel3-sral-demo/lib/python3.12/site-packages/distributed/core.py", line 831, in _handle_comm
    result = await result
  File "/home/abonnin/anaconda3/envs/sentinel3-sral-demo/lib/python3.12/site-packages/distributed/utils.py", line 808, in wrapper
    return await func(*args, **kwargs)
  File "/home/abonnin/anaconda3/envs/sentinel3-sral-demo/lib/python3.12/site-packages/distributed/scheduler.py", line 4602, in add_worker
    await self.handle_worker(comm, address)
  File "/home/abonnin/anaconda3/envs/sentinel3-sral-demo/lib/python3.12/site-packages/distributed/scheduler.py", line 6128, in handle_worker
    await self.remove_worker(
  File "/home/abonnin/anaconda3/envs/sentinel3-sral-demo/lib/python3.12/site-packages/distributed/utils.py", line 808, in wrapper
    return await func(*args, **kwargs)
  File "/home/abonnin/anaconda3/envs/sentinel3-sral-demo/lib/python3.12/site-packages/distributed/scheduler.py", line 5388, in remove_worker
    logger.info(f"Remove worker {ws} ({stimulus_id=})")
Message: "Remove worker <WorkerState 'tcp://127.0.0.1:46019', name: 1, status: closing, memory: 0, processing: 0> (stimulus_id='handle-worker-cleanup-1727764396.0906117')"
Arguments: ()
--- Logging error ---
Traceback (most recent call last):
  File "/home/abonnin/anaconda3/envs/sentinel3-sral-demo/lib/python3.12/logging/__init__.py", line 1163, in emit
    stream.write(msg + self.terminator)
ValueError: I/O operation on closed file.
Call stack:
  File "/home/abonnin/anaconda3/envs/sentinel3-sral-demo/lib/python3.12/threading.py", line 1032, in _bootstrap
    self._bootstrap_inner()
  File "/home/abonnin/anaconda3/envs/sentinel3-sral-demo/lib/python3.12/threading.py", line 1075, in _bootstrap_inner
    self.run()
  File "/home/abonnin/anaconda3/envs/sentinel3-sral-demo/lib/python3.12/threading.py", line 1012, in run
    self._target(*self._args, **self._kwargs)
  File "/home/abonnin/anaconda3/envs/sentinel3-sral-demo/lib/python3.12/site-packages/distributed/utils.py", line 451, in wrapper
    target()
  File "/home/abonnin/anaconda3/envs/sentinel3-sral-demo/lib/python3.12/site-packages/distributed/utils.py", line 559, in run_loop
    asyncio_run(amain(), loop_factory=get_loop_factory())
  File "/home/abonnin/anaconda3/envs/sentinel3-sral-demo/lib/python3.12/asyncio/runners.py", line 194, in run
    return runner.run(main)
  File "/home/abonnin/anaconda3/envs/sentinel3-sral-demo/lib/python3.12/asyncio/runners.py", line 118, in run
    return self._loop.run_until_complete(task)
  File "/home/abonnin/anaconda3/envs/sentinel3-sral-demo/lib/python3.12/asyncio/base_events.py", line 674, in run_until_complete
    self.run_forever()
  File "/home/abonnin/anaconda3/envs/sentinel3-sral-demo/lib/python3.12/asyncio/base_events.py", line 641, in run_forever
    self._run_once()
  File "/home/abonnin/anaconda3/envs/sentinel3-sral-demo/lib/python3.12/asyncio/base_events.py", line 1986, in _run_once
    handle._run()
  File "/home/abonnin/anaconda3/envs/sentinel3-sral-demo/lib/python3.12/asyncio/events.py", line 88, in _run
    self._context.run(self._callback, *self._args)
  File "/home/abonnin/anaconda3/envs/sentinel3-sral-demo/lib/python3.12/site-packages/distributed/core.py", line 831, in _handle_comm
    result = await result
  File "/home/abonnin/anaconda3/envs/sentinel3-sral-demo/lib/python3.12/site-packages/distributed/utils.py", line 808, in wrapper
    return await func(*args, **kwargs)
  File "/home/abonnin/anaconda3/envs/sentinel3-sral-demo/lib/python3.12/site-packages/distributed/scheduler.py", line 4602, in add_worker
    await self.handle_worker(comm, address)
  File "/home/abonnin/anaconda3/envs/sentinel3-sral-demo/lib/python3.12/site-packages/distributed/scheduler.py", line 6128, in handle_worker
    await self.remove_worker(
  File "/home/abonnin/anaconda3/envs/sentinel3-sral-demo/lib/python3.12/site-packages/distributed/utils.py", line 808, in wrapper
    return await func(*args, **kwargs)
  File "/home/abonnin/anaconda3/envs/sentinel3-sral-demo/lib/python3.12/site-packages/distributed/scheduler.py", line 5388, in remove_worker
    logger.info(f"Remove worker {ws} ({stimulus_id=})")
Message: "Remove worker <WorkerState 'tcp://127.0.0.1:41099', name: 2, status: closing, memory: 0, processing: 0> (stimulus_id='handle-worker-cleanup-1727764396.0918045')"
Arguments: ()
--- Logging error ---
Traceback (most recent call last):
  File "/home/abonnin/anaconda3/envs/sentinel3-sral-demo/lib/python3.12/logging/__init__.py", line 1163, in emit
    stream.write(msg + self.terminator)
ValueError: I/O operation on closed file.
Call stack:
  File "/home/abonnin/anaconda3/envs/sentinel3-sral-demo/lib/python3.12/threading.py", line 1032, in _bootstrap
    self._bootstrap_inner()
  File "/home/abonnin/anaconda3/envs/sentinel3-sral-demo/lib/python3.12/threading.py", line 1075, in _bootstrap_inner
    self.run()
  File "/home/abonnin/anaconda3/envs/sentinel3-sral-demo/lib/python3.12/threading.py", line 1012, in run
    self._target(*self._args, **self._kwargs)
  File "/home/abonnin/anaconda3/envs/sentinel3-sral-demo/lib/python3.12/site-packages/distributed/utils.py", line 451, in wrapper
    target()
  File "/home/abonnin/anaconda3/envs/sentinel3-sral-demo/lib/python3.12/site-packages/distributed/utils.py", line 559, in run_loop
    asyncio_run(amain(), loop_factory=get_loop_factory())
  File "/home/abonnin/anaconda3/envs/sentinel3-sral-demo/lib/python3.12/asyncio/runners.py", line 194, in run
    return runner.run(main)
  File "/home/abonnin/anaconda3/envs/sentinel3-sral-demo/lib/python3.12/asyncio/runners.py", line 118, in run
    return self._loop.run_until_complete(task)
  File "/home/abonnin/anaconda3/envs/sentinel3-sral-demo/lib/python3.12/asyncio/base_events.py", line 674, in run_until_complete
    self.run_forever()
  File "/home/abonnin/anaconda3/envs/sentinel3-sral-demo/lib/python3.12/asyncio/base_events.py", line 641, in run_forever
    self._run_once()
  File "/home/abonnin/anaconda3/envs/sentinel3-sral-demo/lib/python3.12/asyncio/base_events.py", line 1986, in _run_once
    handle._run()
  File "/home/abonnin/anaconda3/envs/sentinel3-sral-demo/lib/python3.12/asyncio/events.py", line 88, in _run
    self._context.run(self._callback, *self._args)
  File "/home/abonnin/anaconda3/envs/sentinel3-sral-demo/lib/python3.12/site-packages/distributed/core.py", line 831, in _handle_comm
    result = await result
  File "/home/abonnin/anaconda3/envs/sentinel3-sral-demo/lib/python3.12/site-packages/distributed/utils.py", line 808, in wrapper
    return await func(*args, **kwargs)
  File "/home/abonnin/anaconda3/envs/sentinel3-sral-demo/lib/python3.12/site-packages/distributed/scheduler.py", line 4602, in add_worker
    await self.handle_worker(comm, address)
  File "/home/abonnin/anaconda3/envs/sentinel3-sral-demo/lib/python3.12/site-packages/distributed/scheduler.py", line 6124, in handle_worker
    await self.handle_stream(comm=comm, extra={"worker": worker})
  File "/home/abonnin/anaconda3/envs/sentinel3-sral-demo/lib/python3.12/site-packages/distributed/core.py", line 905, in handle_stream
    logger.info(
Message: "Received 'close-stream' from %s; closing."
Arguments: ('tcp://127.0.0.1:34386',)
--- Logging error ---
Traceback (most recent call last):
  File "/home/abonnin/anaconda3/envs/sentinel3-sral-demo/lib/python3.12/logging/__init__.py", line 1163, in emit
    stream.write(msg + self.terminator)
ValueError: I/O operation on closed file.
Call stack:
  File "/home/abonnin/anaconda3/envs/sentinel3-sral-demo/lib/python3.12/threading.py", line 1032, in _bootstrap
    self._bootstrap_inner()
  File "/home/abonnin/anaconda3/envs/sentinel3-sral-demo/lib/python3.12/threading.py", line 1075, in _bootstrap_inner
    self.run()
  File "/home/abonnin/anaconda3/envs/sentinel3-sral-demo/lib/python3.12/threading.py", line 1012, in run
    self._target(*self._args, **self._kwargs)
  File "/home/abonnin/anaconda3/envs/sentinel3-sral-demo/lib/python3.12/site-packages/distributed/utils.py", line 451, in wrapper
    target()
  File "/home/abonnin/anaconda3/envs/sentinel3-sral-demo/lib/python3.12/site-packages/distributed/utils.py", line 559, in run_loop
    asyncio_run(amain(), loop_factory=get_loop_factory())
  File "/home/abonnin/anaconda3/envs/sentinel3-sral-demo/lib/python3.12/asyncio/runners.py", line 194, in run
    return runner.run(main)
  File "/home/abonnin/anaconda3/envs/sentinel3-sral-demo/lib/python3.12/asyncio/runners.py", line 118, in run
    return self._loop.run_until_complete(task)
  File "/home/abonnin/anaconda3/envs/sentinel3-sral-demo/lib/python3.12/asyncio/base_events.py", line 674, in run_until_complete
    self.run_forever()
  File "/home/abonnin/anaconda3/envs/sentinel3-sral-demo/lib/python3.12/asyncio/base_events.py", line 641, in run_forever
    self._run_once()
  File "/home/abonnin/anaconda3/envs/sentinel3-sral-demo/lib/python3.12/asyncio/base_events.py", line 1986, in _run_once
    handle._run()
  File "/home/abonnin/anaconda3/envs/sentinel3-sral-demo/lib/python3.12/asyncio/events.py", line 88, in _run
    self._context.run(self._callback, *self._args)
  File "/home/abonnin/anaconda3/envs/sentinel3-sral-demo/lib/python3.12/site-packages/distributed/core.py", line 831, in _handle_comm
    result = await result
  File "/home/abonnin/anaconda3/envs/sentinel3-sral-demo/lib/python3.12/site-packages/distributed/utils.py", line 808, in wrapper
    return await func(*args, **kwargs)
  File "/home/abonnin/anaconda3/envs/sentinel3-sral-demo/lib/python3.12/site-packages/distributed/scheduler.py", line 4602, in add_worker
    await self.handle_worker(comm, address)
  File "/home/abonnin/anaconda3/envs/sentinel3-sral-demo/lib/python3.12/site-packages/distributed/scheduler.py", line 6128, in handle_worker
    await self.remove_worker(
  File "/home/abonnin/anaconda3/envs/sentinel3-sral-demo/lib/python3.12/site-packages/distributed/utils.py", line 808, in wrapper
    return await func(*args, **kwargs)
  File "/home/abonnin/anaconda3/envs/sentinel3-sral-demo/lib/python3.12/site-packages/distributed/scheduler.py", line 5388, in remove_worker
    logger.info(f"Remove worker {ws} ({stimulus_id=})")
Message: "Remove worker <WorkerState 'tcp://127.0.0.1:38523', name: 3, status: closing, memory: 0, processing: 0> (stimulus_id='handle-worker-cleanup-1727764396.0946066')"
Arguments: ()
--- Logging error ---
Traceback (most recent call last):
  File "/home/abonnin/anaconda3/envs/sentinel3-sral-demo/lib/python3.12/logging/__init__.py", line 1163, in emit
    stream.write(msg + self.terminator)
ValueError: I/O operation on closed file.
Call stack:
  File "/home/abonnin/anaconda3/envs/sentinel3-sral-demo/lib/python3.12/threading.py", line 1032, in _bootstrap
    self._bootstrap_inner()
  File "/home/abonnin/anaconda3/envs/sentinel3-sral-demo/lib/python3.12/threading.py", line 1075, in _bootstrap_inner
    self.run()
  File "/home/abonnin/anaconda3/envs/sentinel3-sral-demo/lib/python3.12/threading.py", line 1012, in run
    self._target(*self._args, **self._kwargs)
  File "/home/abonnin/anaconda3/envs/sentinel3-sral-demo/lib/python3.12/site-packages/distributed/utils.py", line 451, in wrapper
    target()
  File "/home/abonnin/anaconda3/envs/sentinel3-sral-demo/lib/python3.12/site-packages/distributed/utils.py", line 559, in run_loop
    asyncio_run(amain(), loop_factory=get_loop_factory())
  File "/home/abonnin/anaconda3/envs/sentinel3-sral-demo/lib/python3.12/asyncio/runners.py", line 194, in run
    return runner.run(main)
  File "/home/abonnin/anaconda3/envs/sentinel3-sral-demo/lib/python3.12/asyncio/runners.py", line 118, in run
    return self._loop.run_until_complete(task)
  File "/home/abonnin/anaconda3/envs/sentinel3-sral-demo/lib/python3.12/asyncio/base_events.py", line 674, in run_until_complete
    self.run_forever()
  File "/home/abonnin/anaconda3/envs/sentinel3-sral-demo/lib/python3.12/asyncio/base_events.py", line 641, in run_forever
    self._run_once()
  File "/home/abonnin/anaconda3/envs/sentinel3-sral-demo/lib/python3.12/asyncio/base_events.py", line 1986, in _run_once
    handle._run()
  File "/home/abonnin/anaconda3/envs/sentinel3-sral-demo/lib/python3.12/asyncio/events.py", line 88, in _run
    self._context.run(self._callback, *self._args)
  File "/home/abonnin/anaconda3/envs/sentinel3-sral-demo/lib/python3.12/site-packages/distributed/core.py", line 831, in _handle_comm
    result = await result
  File "/home/abonnin/anaconda3/envs/sentinel3-sral-demo/lib/python3.12/site-packages/distributed/utils.py", line 808, in wrapper
    return await func(*args, **kwargs)
  File "/home/abonnin/anaconda3/envs/sentinel3-sral-demo/lib/python3.12/site-packages/distributed/scheduler.py", line 4602, in add_worker
    await self.handle_worker(comm, address)
  File "/home/abonnin/anaconda3/envs/sentinel3-sral-demo/lib/python3.12/site-packages/distributed/scheduler.py", line 6124, in handle_worker
    await self.handle_stream(comm=comm, extra={"worker": worker})
  File "/home/abonnin/anaconda3/envs/sentinel3-sral-demo/lib/python3.12/site-packages/distributed/core.py", line 905, in handle_stream
    logger.info(
Message: "Received 'close-stream' from %s; closing."
Arguments: ('tcp://127.0.0.1:34372',)
--- Logging error ---
Traceback (most recent call last):
  File "/home/abonnin/anaconda3/envs/sentinel3-sral-demo/lib/python3.12/site-packages/distributed/batched.py", line 115, in _background_send
    nbytes = yield coro
             ^^^^^^^^^^
  File "/home/abonnin/anaconda3/envs/sentinel3-sral-demo/lib/python3.12/site-packages/tornado/gen.py", line 766, in run
    value = future.result()
            ^^^^^^^^^^^^^^^
  File "/home/abonnin/anaconda3/envs/sentinel3-sral-demo/lib/python3.12/site-packages/distributed/comm/tcp.py", line 262, in write
    raise CommClosedError()
distributed.comm.core.CommClosedError

During handling of the above exception, another exception occurred:

Traceback (most recent call last):
  File "/home/abonnin/anaconda3/envs/sentinel3-sral-demo/lib/python3.12/logging/__init__.py", line 1163, in emit
    stream.write(msg + self.terminator)
ValueError: I/O operation on closed file.
Call stack:
  File "/home/abonnin/anaconda3/envs/sentinel3-sral-demo/lib/python3.12/threading.py", line 1032, in _bootstrap
    self._bootstrap_inner()
  File "/home/abonnin/anaconda3/envs/sentinel3-sral-demo/lib/python3.12/threading.py", line 1075, in _bootstrap_inner
    self.run()
  File "/home/abonnin/anaconda3/envs/sentinel3-sral-demo/lib/python3.12/threading.py", line 1012, in run
    self._target(*self._args, **self._kwargs)
  File "/home/abonnin/anaconda3/envs/sentinel3-sral-demo/lib/python3.12/site-packages/distributed/utils.py", line 451, in wrapper
    target()
  File "/home/abonnin/anaconda3/envs/sentinel3-sral-demo/lib/python3.12/site-packages/distributed/utils.py", line 559, in run_loop
    asyncio_run(amain(), loop_factory=get_loop_factory())
  File "/home/abonnin/anaconda3/envs/sentinel3-sral-demo/lib/python3.12/asyncio/runners.py", line 194, in run
    return runner.run(main)
  File "/home/abonnin/anaconda3/envs/sentinel3-sral-demo/lib/python3.12/asyncio/runners.py", line 118, in run
    return self._loop.run_until_complete(task)
  File "/home/abonnin/anaconda3/envs/sentinel3-sral-demo/lib/python3.12/asyncio/base_events.py", line 674, in run_until_complete
    self.run_forever()
  File "/home/abonnin/anaconda3/envs/sentinel3-sral-demo/lib/python3.12/asyncio/base_events.py", line 641, in run_forever
    self._run_once()
  File "/home/abonnin/anaconda3/envs/sentinel3-sral-demo/lib/python3.12/asyncio/base_events.py", line 1986, in _run_once
    handle._run()
  File "/home/abonnin/anaconda3/envs/sentinel3-sral-demo/lib/python3.12/asyncio/events.py", line 88, in _run
    self._context.run(self._callback, *self._args)
  File "/home/abonnin/anaconda3/envs/sentinel3-sral-demo/lib/python3.12/site-packages/tornado/ioloop.py", line 699, in <lambda>
    lambda f: self._run_callback(functools.partial(callback, f))
  File "/home/abonnin/anaconda3/envs/sentinel3-sral-demo/lib/python3.12/site-packages/tornado/ioloop.py", line 750, in _run_callback
    ret = callback()
  File "/home/abonnin/anaconda3/envs/sentinel3-sral-demo/lib/python3.12/site-packages/tornado/gen.py", line 824, in inner
    self.ctx_run(self.run)
  File "/home/abonnin/anaconda3/envs/sentinel3-sral-demo/lib/python3.12/site-packages/tornado/gen.py", line 779, in run
    yielded = self.gen.throw(exc)
  File "/home/abonnin/anaconda3/envs/sentinel3-sral-demo/lib/python3.12/site-packages/distributed/batched.py", line 122, in _background_send
    logger.info("Batched Comm Closed %r", self.comm, exc_info=True)
Message: 'Batched Comm Closed %r'
Arguments: (<TCP (closed) Scheduler connection to worker local=tcp://127.0.0.1:37221 remote=tcp://127.0.0.1:34386>,)
--- Logging error ---
Traceback (most recent call last):
  File "/home/abonnin/anaconda3/envs/sentinel3-sral-demo/lib/python3.12/logging/__init__.py", line 1163, in emit
    stream.write(msg + self.terminator)
ValueError: I/O operation on closed file.
Call stack:
  File "/home/abonnin/anaconda3/envs/sentinel3-sral-demo/lib/python3.12/threading.py", line 1032, in _bootstrap
    self._bootstrap_inner()
  File "/home/abonnin/anaconda3/envs/sentinel3-sral-demo/lib/python3.12/threading.py", line 1075, in _bootstrap_inner
    self.run()
  File "/home/abonnin/anaconda3/envs/sentinel3-sral-demo/lib/python3.12/threading.py", line 1012, in run
    self._target(*self._args, **self._kwargs)
  File "/home/abonnin/anaconda3/envs/sentinel3-sral-demo/lib/python3.12/site-packages/distributed/utils.py", line 451, in wrapper
    target()
  File "/home/abonnin/anaconda3/envs/sentinel3-sral-demo/lib/python3.12/site-packages/distributed/utils.py", line 559, in run_loop
    asyncio_run(amain(), loop_factory=get_loop_factory())
  File "/home/abonnin/anaconda3/envs/sentinel3-sral-demo/lib/python3.12/asyncio/runners.py", line 194, in run
    return runner.run(main)
  File "/home/abonnin/anaconda3/envs/sentinel3-sral-demo/lib/python3.12/asyncio/runners.py", line 118, in run
    return self._loop.run_until_complete(task)
  File "/home/abonnin/anaconda3/envs/sentinel3-sral-demo/lib/python3.12/asyncio/base_events.py", line 674, in run_until_complete
    self.run_forever()
  File "/home/abonnin/anaconda3/envs/sentinel3-sral-demo/lib/python3.12/asyncio/base_events.py", line 641, in run_forever
    self._run_once()
  File "/home/abonnin/anaconda3/envs/sentinel3-sral-demo/lib/python3.12/asyncio/base_events.py", line 1986, in _run_once
    handle._run()
  File "/home/abonnin/anaconda3/envs/sentinel3-sral-demo/lib/python3.12/asyncio/events.py", line 88, in _run
    self._context.run(self._callback, *self._args)
  File "/home/abonnin/anaconda3/envs/sentinel3-sral-demo/lib/python3.12/site-packages/distributed/core.py", line 831, in _handle_comm
    result = await result
  File "/home/abonnin/anaconda3/envs/sentinel3-sral-demo/lib/python3.12/site-packages/distributed/utils.py", line 808, in wrapper
    return await func(*args, **kwargs)
  File "/home/abonnin/anaconda3/envs/sentinel3-sral-demo/lib/python3.12/site-packages/distributed/scheduler.py", line 4602, in add_worker
    await self.handle_worker(comm, address)
  File "/home/abonnin/anaconda3/envs/sentinel3-sral-demo/lib/python3.12/site-packages/distributed/scheduler.py", line 6128, in handle_worker
    await self.remove_worker(
  File "/home/abonnin/anaconda3/envs/sentinel3-sral-demo/lib/python3.12/site-packages/distributed/utils.py", line 808, in wrapper
    return await func(*args, **kwargs)
  File "/home/abonnin/anaconda3/envs/sentinel3-sral-demo/lib/python3.12/site-packages/distributed/scheduler.py", line 5388, in remove_worker
    logger.info(f"Remove worker {ws} ({stimulus_id=})")
Message: "Remove worker <WorkerState 'tcp://127.0.0.1:39037', name: 4, status: closing, memory: 0, processing: 0> (stimulus_id='handle-worker-cleanup-1727764396.1024466')"
Arguments: ()
--- Logging error ---
Traceback (most recent call last):
  File "/home/abonnin/anaconda3/envs/sentinel3-sral-demo/lib/python3.12/logging/__init__.py", line 1163, in emit
    stream.write(msg + self.terminator)
ValueError: I/O operation on closed file.
Call stack:
  File "/home/abonnin/anaconda3/envs/sentinel3-sral-demo/lib/python3.12/threading.py", line 1032, in _bootstrap
    self._bootstrap_inner()
  File "/home/abonnin/anaconda3/envs/sentinel3-sral-demo/lib/python3.12/threading.py", line 1075, in _bootstrap_inner
    self.run()
  File "/home/abonnin/anaconda3/envs/sentinel3-sral-demo/lib/python3.12/threading.py", line 1012, in run
    self._target(*self._args, **self._kwargs)
  File "/home/abonnin/anaconda3/envs/sentinel3-sral-demo/lib/python3.12/site-packages/distributed/utils.py", line 451, in wrapper
    target()
  File "/home/abonnin/anaconda3/envs/sentinel3-sral-demo/lib/python3.12/site-packages/distributed/utils.py", line 559, in run_loop
    asyncio_run(amain(), loop_factory=get_loop_factory())
  File "/home/abonnin/anaconda3/envs/sentinel3-sral-demo/lib/python3.12/asyncio/runners.py", line 194, in run
    return runner.run(main)
  File "/home/abonnin/anaconda3/envs/sentinel3-sral-demo/lib/python3.12/asyncio/runners.py", line 118, in run
    return self._loop.run_until_complete(task)
  File "/home/abonnin/anaconda3/envs/sentinel3-sral-demo/lib/python3.12/asyncio/base_events.py", line 674, in run_until_complete
    self.run_forever()
  File "/home/abonnin/anaconda3/envs/sentinel3-sral-demo/lib/python3.12/asyncio/base_events.py", line 641, in run_forever
    self._run_once()
  File "/home/abonnin/anaconda3/envs/sentinel3-sral-demo/lib/python3.12/asyncio/base_events.py", line 1986, in _run_once
    handle._run()
  File "/home/abonnin/anaconda3/envs/sentinel3-sral-demo/lib/python3.12/asyncio/events.py", line 88, in _run
    self._context.run(self._callback, *self._args)
  File "/home/abonnin/anaconda3/envs/sentinel3-sral-demo/lib/python3.12/site-packages/distributed/core.py", line 831, in _handle_comm
    result = await result
  File "/home/abonnin/anaconda3/envs/sentinel3-sral-demo/lib/python3.12/site-packages/distributed/utils.py", line 808, in wrapper
    return await func(*args, **kwargs)
  File "/home/abonnin/anaconda3/envs/sentinel3-sral-demo/lib/python3.12/site-packages/distributed/scheduler.py", line 4602, in add_worker
    await self.handle_worker(comm, address)
  File "/home/abonnin/anaconda3/envs/sentinel3-sral-demo/lib/python3.12/site-packages/distributed/scheduler.py", line 6128, in handle_worker
    await self.remove_worker(
  File "/home/abonnin/anaconda3/envs/sentinel3-sral-demo/lib/python3.12/site-packages/distributed/utils.py", line 808, in wrapper
    return await func(*args, **kwargs)
  File "/home/abonnin/anaconda3/envs/sentinel3-sral-demo/lib/python3.12/site-packages/distributed/scheduler.py", line 5521, in remove_worker
    logger.info("Lost all workers")
Message: 'Lost all workers'
Arguments: ()
--- Logging error ---
Traceback (most recent call last):
  File "/home/abonnin/anaconda3/envs/sentinel3-sral-demo/lib/python3.12/logging/__init__.py", line 1163, in emit
    stream.write(msg + self.terminator)
ValueError: I/O operation on closed file.
Call stack:
  File "/home/abonnin/anaconda3/envs/sentinel3-sral-demo/lib/python3.12/threading.py", line 1032, in _bootstrap
    self._bootstrap_inner()
  File "/home/abonnin/anaconda3/envs/sentinel3-sral-demo/lib/python3.12/threading.py", line 1075, in _bootstrap_inner
    self.run()
  File "/home/abonnin/anaconda3/envs/sentinel3-sral-demo/lib/python3.12/threading.py", line 1012, in run
    self._target(*self._args, **self._kwargs)
  File "/home/abonnin/anaconda3/envs/sentinel3-sral-demo/lib/python3.12/site-packages/distributed/utils.py", line 451, in wrapper
    target()
  File "/home/abonnin/anaconda3/envs/sentinel3-sral-demo/lib/python3.12/site-packages/distributed/utils.py", line 559, in run_loop
    asyncio_run(amain(), loop_factory=get_loop_factory())
  File "/home/abonnin/anaconda3/envs/sentinel3-sral-demo/lib/python3.12/asyncio/runners.py", line 194, in run
    return runner.run(main)
  File "/home/abonnin/anaconda3/envs/sentinel3-sral-demo/lib/python3.12/asyncio/runners.py", line 118, in run
    return self._loop.run_until_complete(task)
  File "/home/abonnin/anaconda3/envs/sentinel3-sral-demo/lib/python3.12/asyncio/base_events.py", line 674, in run_until_complete
    self.run_forever()
  File "/home/abonnin/anaconda3/envs/sentinel3-sral-demo/lib/python3.12/asyncio/base_events.py", line 641, in run_forever
    self._run_once()
  File "/home/abonnin/anaconda3/envs/sentinel3-sral-demo/lib/python3.12/asyncio/base_events.py", line 1986, in _run_once
    handle._run()
  File "/home/abonnin/anaconda3/envs/sentinel3-sral-demo/lib/python3.12/asyncio/events.py", line 88, in _run
    self._context.run(self._callback, *self._args)
  File "/home/abonnin/anaconda3/envs/sentinel3-sral-demo/lib/python3.12/site-packages/distributed/core.py", line 831, in _handle_comm
    result = await result
  File "/home/abonnin/anaconda3/envs/sentinel3-sral-demo/lib/python3.12/site-packages/distributed/scheduler.py", line 4293, in close
    logger.info("Closing scheduler. Reason: %s", reason)
Message: 'Closing scheduler. Reason: %s'
Arguments: ('unknown',)
--- Logging error ---
Traceback (most recent call last):
  File "/home/abonnin/anaconda3/envs/sentinel3-sral-demo/lib/python3.12/logging/__init__.py", line 1163, in emit
    stream.write(msg + self.terminator)
ValueError: I/O operation on closed file.
Call stack:
  File "/home/abonnin/anaconda3/envs/sentinel3-sral-demo/lib/python3.12/threading.py", line 1032, in _bootstrap
    self._bootstrap_inner()
  File "/home/abonnin/anaconda3/envs/sentinel3-sral-demo/lib/python3.12/threading.py", line 1075, in _bootstrap_inner
    self.run()
  File "/home/abonnin/anaconda3/envs/sentinel3-sral-demo/lib/python3.12/threading.py", line 1012, in run
    self._target(*self._args, **self._kwargs)
  File "/home/abonnin/anaconda3/envs/sentinel3-sral-demo/lib/python3.12/site-packages/distributed/utils.py", line 451, in wrapper
    target()
  File "/home/abonnin/anaconda3/envs/sentinel3-sral-demo/lib/python3.12/site-packages/distributed/utils.py", line 559, in run_loop
    asyncio_run(amain(), loop_factory=get_loop_factory())
  File "/home/abonnin/anaconda3/envs/sentinel3-sral-demo/lib/python3.12/asyncio/runners.py", line 194, in run
    return runner.run(main)
  File "/home/abonnin/anaconda3/envs/sentinel3-sral-demo/lib/python3.12/asyncio/runners.py", line 118, in run
    return self._loop.run_until_complete(task)
  File "/home/abonnin/anaconda3/envs/sentinel3-sral-demo/lib/python3.12/asyncio/base_events.py", line 674, in run_until_complete
    self.run_forever()
  File "/home/abonnin/anaconda3/envs/sentinel3-sral-demo/lib/python3.12/asyncio/base_events.py", line 641, in run_forever
    self._run_once()
  File "/home/abonnin/anaconda3/envs/sentinel3-sral-demo/lib/python3.12/asyncio/base_events.py", line 1986, in _run_once
    handle._run()
  File "/home/abonnin/anaconda3/envs/sentinel3-sral-demo/lib/python3.12/asyncio/events.py", line 88, in _run
    self._context.run(self._callback, *self._args)
  File "/home/abonnin/anaconda3/envs/sentinel3-sral-demo/lib/python3.12/site-packages/distributed/core.py", line 831, in _handle_comm
    result = await result
  File "/home/abonnin/anaconda3/envs/sentinel3-sral-demo/lib/python3.12/site-packages/distributed/scheduler.py", line 4321, in close
    logger.info("Scheduler closing all comms")
Message: 'Scheduler closing all comms'
Arguments: ()
